Workbook

Sheet Annual Financial
A1: Balance Sheet | I1: Income Statement | Q1: Cash Flow | Y1: Ratios | AG1: Revune By Segment
A2: Fiscal Year | B2: TTM | C2: FY 2024 | D2: FY 2023 | E2: FY 2022 | F2: FY 2021 | G2: FY 2020 | I2: Fiscal Year | J2: TTM | K2: FY 2024 | L2: FY 2023 | M2: FY 2022 | N2: FY 2021 | O2: FY 2020 | Q2: Fiscal Year | R2: TTM | S2: FY 2024 | T2: FY 2023 | U2: FY 2022 | V2: FY 2021 | W2: FY 2020 | Y2: Fiscal Year | Z2: Current | AA2: FY 2024 | AB2: FY 2023 | AC2: FY 2022 | AD2: FY 2021 | AE2: FY 2020 | AG2: Date | AH2: Google Search & Other | AI2: Advertising | AJ2: Google Cloud | AK2: Google Subscriptions, Platforms & Devices | AL2: YouTube Ads | AM2: Google Network | AN2: Other Bets | AO2: Hedging Gains
A3: Period Ending | B3: 45838 | C3: 45657 | D3: 45291 | E3: 44926 | F3: 44561 | G3: 44196 | I3: Period Ending | J3: 45838 | K3: 45657 | L3: 45291 | M3: 44926 | N3: 44561 | O3: 44196 | Q3: Period Ending | R3: 45838 | S3: 45657 | T3: 45291 | U3: 44926 | V3: 44561 | W3: 44196 | Y3: Period Ending | Z3: 45933 | AA3: 45657 | AB3: 45291 | AC3: 44926 | AD3: 44561 | AE3: 44196 | AG3: 45838 | AH3: 208.31B | AI3: 110.91B | AJ3: 49.19B | AK3: 43.87B | AL3: 38.12B | AM3: 30.11B | AN3: 1.61B | AO3: 185.00M
A4: Cash & Equivalents | B4: 21036 | C4: 23466 | D4: 24048 | E4: 21879 | F4: 20945 | G4: 26465 | I4: Revenue | J4: 371399 | K4: 350018 | L4: 307394 | M4: 282836 | N4: 257637 | O4: 182527 | Q4: Net Income | R4: 115573 | S4: 100118 | T4: 73795 | U4: 59972 | V4: 76033 | W4: 40269 | Y4: Market Capitalization | Z4: 2960974 | AA4: 2323530 | AB4: 1755459 | AC4: 1145004 | AD4: 1921855 | AE4: 1185281 | AG4: 45747 | AH4: 202.63B | AI4: 106.02B | AJ4: 45.92B | AK4: 41.98B | AL4: 36.98B | AM4: 30.20B | AN4: 1.60B | AO4: 300.00M
A5: Short-Term Investments | B5: 74112 | C5: 72191 | D5: 86868 | E5: 91883 | F5: 118704 | G5: 110229 | I5: Revenue Growth (YoY) | J5: 0.1313 | K5: 0.1387 | L5: 0.0868 | M5: 0.0978 | N5: 0.4115 | O5: 0.1277 | Q5: Depreciation & Amortization | R5: 17675 | S5: 15311 | T5: 11946 | U5: 13475 | V5: 10273 | W5: 13679 | Y5: Market Cap Growth | Z5: 0.5098 | AA5: 0.3236 | AB5: 0.5331 | AC5: -0.4042 | AD5: 0.6214 | AE5: 0.2842 | AG5: 45657 | AH5: 198.08B | AI5: 100.61B | AJ5: 43.23B | AK5: 40.34B | AL5: 36.15B | AM5: 30.36B | AN5: 1.65B | AO5: 112.00M
A6: Cash & Short-Term Investments | B6: 95148 | C6: 95657 | D6: 110916 | E6: 113762 | F6: 139649 | G6: 136694 | I6: Cost of Revenue | J6: 152487 | K6: 146306 | L6: 133332 | M6: 126203 | N6: 110939 | O6: 84732 | Q6: Asset Writedown & Restructuring Costs | R6: - | S6: - | T6: - | U6: - | V6: - | W6: 18 | Y6: Enterprise Value | Z6: 2917895 | AA6: 2259589 | AB6: 1665970 | AC6: 1058081 | AD6: 1807518 | AE6: 1079780 | AG6: 45565 | AH6: 192.07B | AI6: 95.38B | AJ6: 40.47B | AK6: 39.50B | AL6: 34.87B | AM6: 30.70B | AN6: 1.91B | AO6: 242.00M
A7: Cash Growth | B7: -0.0554 | C7: -0.1376 | D7: -0.025 | E7: -0.1854 | F7: 0.0216 | G7: 0.1422 | I7: Gross Profit | J7: 218912 | K7: 203712 | L7: 174062 | M7: 156633 | N7: 146698 | O7: 97795 | Q7: Loss (Gain) From Sale of Investments | R7: -13325 | S7: -2671 | T7: 823 | U7: 5519 | V7: -12270 | W7: -6317 | Y7: Last Close Price | Z7: 245.69 | AA7: 188.68 | AB7: 138.73 | AC7: 87.63 | AD7: 143.86 | AE7: 87.03 | AG7: 45473 | AH7: 186.71B | AI7: 90.55B | AJ7: 37.52B | AK7: 37.18B | AL7: 33.91B | AM7: 30.82B | AN7: 1.81B | AO7: 224.00M
A8: Accounts Receivable | B8: 55048 | C8: 52340 | D8: 47964 | E8: 40258 | F8: 39304 | G8: 30930 | I8: Selling, General & Admin | J8: 44615 | K8: 41996 | L8: 44342 | M8: 42291 | N8: 36422 | O8: 28998 | Q8: Stock-Based Compensation | R8: 23170 | S8: 22785 | T8: 22460 | U8: 19362 | V8: 15376 | W8: 12991 | Y8: PE Ratio | Z8: 26.09 | AA8: 23.21 | AB8: 23.79 | AC8: 19.09 | AD8: 25.28 | AE8: 29.43 | AG8: 45382 | AH8: 180.83B | AI8: 86.30B | AJ8: 35.21B | AK8: 36.01B | AL8: 32.91B | AM8: 31.23B | AN8: 1.73B | AO8: 224.00M
A9: Receivables | B9: 55048 | C9: 52340 | D9: 47964 | E9: 40258 | F9: 39304 | G9: 31384 | I9: Research & Development | J9: 51131 | K9: 47530 | L9: 45427 | M9: 39500 | N9: 31562 | O9: 27573 | Q9: Other Operating Activities | R9: -840 | S9: -1838 | T9: -3433 | U9: -4598 | V9: 3763 | W9: 2657 | Y9: Forward PE | Z9: 24.65 | AA9: 22.05 | AB9: 21.69 | AC9: 17.89 | AD9: 26.61 | AE9: 29.57 | AG9: 45291 | AH9: 175.03B | AI9: 82.77B | AJ9: 33.09B | AK9: 34.69B | AL9: 31.51B | AM9: 31.31B | AN9: 1.53B | AO9: 236.00M
A10: Other Current Assets | B10: 16020 | C10: 15714 | D10: 12650 | E10: 10775 | F10: 8020 | G10: 5490 | I10: Operating Expenses | J10: 95746 | K10: 89526 | L10: 89769 | M10: 81791 | N10: 67984 | O10: 56571 | Q10: Change in Accounts Receivable | R10: -7202 | S10: -5891 | T10: -7833 | U10: -2317 | V10: -9095 | W10: -6524 | Y10: PS Ratio | Z10: 8.07 | AA10: 6.64 | AB10: 5.71 | AC10: 4.05 | AD10: 7.46 | AE10: 6.49 | AG10: 45199 | AH10: 169.62B | AI10: 79.38B | AJ10: 31.21B | AK10: 32.69B | AL10: 30.27B | AM10: 31.49B | AN10: 1.10B | AO10: 755.00M
A11: Total Current Assets | B11: 166216 | C11: 163711 | D11: 171530 | E11: 164795 | F11: 188143 | G11: 174296 | I11: Operating Income | J11: 123166 | K11: 114186 | L11: 84293 | M11: 74842 | N11: 78714 | O11: 41224 | Q11: Change in Accounts Payable | R11: 595 | S11: 359 | T11: 664 | U11: 707 | V11: 283 | W11: 694 | Y11: PB Ratio | Z11: 8.19 | AA11: 7.15 | AB11: 6.2 | AC11: 4.47 | AD11: 7.64 | AE11: 5.33 | AG11: 45107 | AH11: 165.13B | AI11: 76.06B | AJ11: 29.67B | AK11: 31.25B | AL11: 29.39B | AM11: 31.69B | AN11: 1.01B | AO11: 1.39B
A12: Property, Plant & Equipment | B12: 217486 | C12: 184624 | D12: 148436 | E12: 127049 | F12: 110558 | G12: 96960 | I12: Interest Expense | J12: -402 | K12: -268 | L12: -308 | M12: -357 | N12: -346 | O12: -135 | Q12: Change in Unearned Revenue | R12: 1459 | S12: 1043 | T12: 525 | U12: 367 | V12: 774 | W12: 635 | Y12: P/TBV Ratio | Z12: 8.99 | AA12: 7.93 | AB12: 6.91 | AC12: 5.04 | AD12: 8.46 | AE12: 5.93 | AG12: 45016 | AH12: 163.19B | AI12: 73.02B | AJ12: 27.91B | AK12: 29.66B | AL12: 29.07B | AM12: 32.10B | AN12: 916.00M | AO12: 1.77B
A13: Long-Term Investments | B13: 52574 | C13: 40882 | D13: 31929 | E13: 30492 | F13: 29549 | G13: 20703 | I13: Interest & Investment Income | J13: 4382 | K13: 4482 | L13: 3865 | M13: 2174 | N13: 1499 | O13: 1865 | Q13: Change in Income Taxes | R13: -3963 | S13: -2418 | T13: 523 | U13: 584 | V13: -625 | W13: 1209 | Y13: P/FCF Ratio | Z13: 44.53 | AA13: 31.93 | AB13: 25.26 | AC13: 19.08 | AD13: 28.68 | AE13: 27.67 | AG13: 44926 | AH13: 162.45B | AI13: - | AJ13: 26.28B | AK13: 29.06B | AL13: 29.24B | AM13: 32.78B | AN13: 1.07B | AO13: 1.96B
A14: Goodwill | B14: 32335 | C14: 31885 | D14: 29198 | E14: 28960 | F14: 22956 | G14: 21175 | I14: Earnings From Equity Investments | J14: 203 | K14: -188 | L14: -628 | M14: -337 | N14: 334 | O14: 401 | Q14: Change in Other Net Operating Assets | R14: 566 | S14: -1499 | T14: 2276 | U14: -1576 | V14: 7140 | W14: 5813 | Y14: P/OCF Ratio | Z14: 22.22 | AA14: 18.54 | AB14: 17.25 | AC14: 12.51 | AD14: 20.97 | AE14: 18.2 | AG14: 44834 | AH14: 163.15B | AI14: - | AJ14: 24.51B | AK14: 28.42B | AL14: 29.91B | AM14: 33.61B | AN14: 1.02B | AO14: 1.49B
A15: Long-Term Deferred Tax Assets | B15: 19289 | C15: 17180 | D15: 12169 | E15: 5261 | F15: 1284 | G15: 1084 | I15: Currency Exchange Gain (Loss) | J15: -173 | K15: -409 | L15: -1238 | M15: -654 | N15: -240 | O15: -344 | Q15: Operating Cash Flow | R15: 133708 | S15: 125299 | T15: 101746 | U15: 91495 | V15: 91652 | W15: 65124 | Y15: PEG Ratio | Z15: 1.6 | AA15: 1.34 | AB15: 1.23 | AC15: 1.03 | AD15: 1.17 | AE15: 1.88 | AG15: 44742 | AH15: 161.53B | AI15: - | AJ15: 22.63B | AK15: 28.28B | AL15: 30.05B | AM15: 33.74B | AN15: 996.00M | AO15: 918.00M
A16: Other Long-Term Assets | B16: 14153 | C16: 11974 | D16: 9130 | E16: 8707 | F16: 5361 | G16: 3953 | I16: Other Non Operating Income (Expenses) | J16: 966 | K16: 1137 | L16: 556 | M16: 1179 | N16: -1497 | O16: -1246 | Q16: Operating Cash Flow Growth | R16: 0.2727 | S16: 0.2315 | T16: 0.112 | U16: -0.0017 | V16: 0.4073 | W16: 0.1945 | Y16: EV/Sales Ratio | Z16: 7.86 | AA16: 6.46 | AB16: 5.42 | AC16: 3.74 | AD16: 7.02 | AE16: 5.92 | AG16: 44651 | AH16: 156.69B | AI16: - | AJ16: 20.98B | AK16: 28.35B | AL16: 29.71B | AM16: 33.08B | AN16: 995.00M | AO16: 536.00M
A17: Total Assets | B17: 502053 | C17: 450256 | D17: 402392 | E17: 365264 | F17: 359268 | G17: 319616 | I17: EBT Excluding Unusual Items | J17: 128142 | K17: 118940 | L17: 86540 | M17: 76847 | N17: 78464 | O17: 41765 | Q17: Capital Expenditures | R17: -66980 | S17: -52535 | T17: -32251 | U17: -31485 | V17: -24640 | W17: -22281 | Y17: EV/EBITDA Ratio | Z17: 20.72 | AA17: 17.45 | AB17: 17.31 | AC17: 11.98 | AD17: 20.31 | AE17: 19.67 | AG17: 44561 | AH17: 148.95B | AI17: - | AJ17: 19.21B | AK17: 28.03B | AL17: 28.85B | AM17: 31.70B | AN17: 753.00M | AO17: 149.00M
A18: Accounts Payable | B18: 8347 | C18: 7987 | D18: 7493 | E18: 5128 | F18: 6037 | G18: 5589 | I18: Merger & Restructuring Charges | J18: -1796 | K18: -1796 | L18: - | M18: - | N18: - | O18: - | Q18: Cash Acquisitions | R18: -3197 | S18: -2931 | T18: -495 | U18: -6969 | V18: -2618 | W18: -738 | Y18: EV/EBIT Ratio | Z18: 23.69 | AA18: 19.79 | AB18: 19.76 | AC18: 14.14 | AD18: 22.96 | AE18: 26.19 | AG18: 44469 | AH18: 137.55B | AI18: - | AJ18: 17.50B | AK18: 26.55B | AL18: 27.10B | AM18: 29.81B | AN18: 768.00M | AO18: -56.00M
A19: Accrued Expenses | B19: 36638 | C19: 41541 | D19: 36142 | E19: 31743 | F19: 27912 | G19: 20445 | I19: Gain (Loss) on Sale of Investments | J19: 13325 | K19: 2671 | L19: -823 | M19: -5519 | N19: 12270 | O19: 6317 | Q19: Investment in Securities | R19: -1754 | S19: 12597 | T19: 6734 | U19: 16567 | V19: -8806 | W19: -9822 | Y19: EV/FCF Ratio | Z19: 43.73 | AA19: 31.05 | AB19: 23.97 | AC19: 17.63 | AD19: 26.97 | AE19: 25.2 | AG19: 44377 | AH19: 125.97B | AI19: - | AJ19: 15.95B | AK19: 25.27B | AL19: 24.93B | AM19: 27.53B | AN19: 764.00M | AO19: -140.00M
A20: Current Portion of Long-Term Debt | B20: 1000 | C20: 999 | D20: 1000 | E20: - | F20: - | G20: 999 | I20: Pretax Income | J20: 139671 | K20: 119815 | L20: 85717 | M20: 71328 | N20: 90734 | O20: 48082 | Q20: Other Investing Activities | R20: -2998 | S20: -2667 | T20: -1051 | U20: 1589 | V20: 541 | W20: 68 | Y20: Debt / Equity Ratio | Z20: 0.12 | AA20: 0.09 | AB20: 0.11 | AC20: 0.12 | AD20: 0.11 | AE20: 0.13 | AG20: 44286 | AH20: 111.44B | AI20: - | AJ20: 14.33B | AK20: 23.77B | AL20: 21.74B | AM20: 24.67B | AN20: 720.00M | AO20: 18.00M
A21: Current Portion of Leases | B21: 3107 | C21: 3122 | D21: 3074 | E21: 2775 | F21: 2302 | G21: 1795 | I21: Income Tax Expense | J21: 24098 | K21: 19697 | L21: 11922 | M21: 11356 | N21: 14701 | O21: 7813 | Q21: Investing Cash Flow | R21: -74929 | S21: -45536 | T21: -27063 | U21: -20298 | V21: -35523 | W21: -32773 | Y21: Debt / EBITDA Ratio | Z21: 0.29 | AA21: 0.21 | AB21: 0.3 | AC21: 0.33 | AD21: 0.31 | AE21: 0.48 | AG21: 44196 | AH21: 104.06B | AI21: - | AJ21: 13.06B | AK21: 21.71B | AL21: 19.77B | AM21: 23.09B | AN21: 657.00M | AO21: 176.00M
A22: Current Income Taxes Payable | B22: 786 | C22: 2905 | D22: 2748 | E22: 1632 | F22: - | G22: 1485 | I22: Earnings From Continuing Operations | J22: 115573 | K22: 100118 | L22: 73795 | M22: 59972 | N22: 76033 | O22: 40269 | Q22: Long-Term Debt Issued | R22: - | S22: 13589 | T22: 10790 | U22: 52872 | V22: 20199 | W22: 11761 | Y22: Debt / FCF Ratio | Z22: 0.62 | AA22: 0.39 | AB22: 0.43 | AC22: 0.5 | AD22: 0.43 | AE22: 0.65 | AG22: 44104 | AH22: 99.34B | AI22: - | AJ22: 11.84B | AK22: 19.09B | AL22: 17.60B | AM22: 21.71B | AN22: 633.00M | AO22: 269.00M
A23: Current Unearned Revenue | B23: 4969 | C23: 5036 | D23: 4137 | E23: 3908 | F23: 3288 | G23: 2543 | I23: Net Income | J23: 115573 | K23: 100118 | L23: 73795 | M23: 59972 | N23: 76033 | O23: 40269 | Q23: Long-Term Debt Repaid | R23: - | S23: -12701 | T23: -11550 | U23: -54068 | V23: -21435 | W23: -2100 | Y23: Asset Turnover | Z23: 0.81 | AA23: 0.82 | AB23: 0.8 | AC23: 0.78 | AD23: 0.76 | AE23: 0.61
A24: Other Current Liabilities | B24: 32463 | C24: 27532 | D24: 27220 | E24: 24114 | F24: 24715 | G24: 23978 | I24: Net Income to Common | J24: 115573 | K24: 100118 | L24: 73795 | M24: 59972 | N24: 76033 | O24: 40269 | Q24: Net Debt Issued (Repaid) | R24: 14496 | S24: 888 | T24: -760 | U24: -1196 | V24: -1236 | W24: 9661 | Y24: Quick Ratio | Z24: 1.72 | AA24: 1.66 | AB24: 1.94 | AC24: 2.22 | AD24: 2.79 | AE24: 2.96
A25: Total Current Liabilities | B25: 87310 | C25: 89122 | D25: 81814 | E25: 69300 | F25: 64254 | G25: 56834 | I25: Net Income Growth | J25: 0.3185 | K25: 0.3567 | L25: 0.2305 | M25: -0.2112 | N25: 0.8881 | O25: 0.1726 | Q25: Repurchase of Common Stock | R25: -59548 | S25: -62222 | T25: -61504 | U25: -59296 | V25: -50274 | W25: -31149 | Y25: Current Ratio | Z25: 1.9 | AA25: 1.84 | AB25: 2.1 | AC25: 2.38 | AD25: 2.93 | AE25: 3.07
A26: Long-Term Debt | B26: 23607 | C26: 10883 | D26: 11870 | E26: 12857 | F26: 12844 | G26: 12832 | I26: Shares Outstanding (Basic) | J26: 12206 | K26: 12319 | L26: 12630 | M26: 13063 | N26: 13353 | O26: 13616 | Q26: Common Dividends Paid | R26: -9874 | S26: -7363 | T26: - | U26: - | V26: - | W26: - | Y26: Return on Equity (ROE) | Z26: 0.3483 | AA26: 0.3291 | AB26: 0.2736 | AC26: 0.2362 | AD26: 0.3207 | AE26: 0.19
A27: Long-Term Leases | B27: 13954 | C27: 13133 | D27: 13843 | E27: 14345 | F27: 13362 | G27: 12246 | I27: Shares Outstanding (Diluted) | J27: 12314 | K27: 12447 | L27: 12722 | M27: 13159 | N27: 13553 | O27: 13741 | Q27: Other Financing Activities | R27: -10237 | S27: -11036 | T27: -9829 | U27: -9265 | V27: -9852 | W27: -2920 | Y27: Return on Assets (ROA) | Z27: 0.1679 | AA27: 0.1674 | AB27: 0.1373 | AC27: 0.1291 | AD27: 0.1449 | AE27: 0.0865
A28: Other Long-Term Liabilities | B28: 14266 | C28: 12034 | D28: 11486 | E28: 11505 | F28: 11381 | G28: 11118 | I28: Shares Change (YoY) | J28: -0.0212 | K28: -0.0216 | L28: -0.0332 | M28: -0.0291 | N28: -0.0137 | O28: -0.0165 | Q28: Financing Cash Flow | R28: -65163 | S28: -79733 | T28: -72093 | U28: -69757 | V28: -61362 | W28: -24408 | Y28: Return on Capital (ROIC) | Z28: 0.2097 | AA28: 0.2142 | AB28: 0.1758 | AC28: 0.1652 | AD28: 0.1855 | AE28: 0.1101
A29: Total Liabilities | B29: 139137 | C29: 125172 | D29: 119013 | E29: 109120 | F29: 107633 | G29: 97072 | I29: EPS (Basic) | J29: 9.47 | K29: 8.13 | L29: 5.84 | M29: 4.59 | N29: 5.69 | O29: 2.96 | Q29: Foreign Exchange Rate Adjustments | R29: 195 | S29: -612 | T29: -421 | U29: -506 | V29: -287 | W29: 24 | Y29: Return on Capital Employed (ROCE) | Z29: 0.297 | AA29: 0.316 | AB29: 0.263 | AC29: 0.253 | AD29: 0.267 | AE29: 0.157
A30: Common Stock | B30: 89283 | C30: 84800 | D30: 76534 | E30: 68184 | F30: 61774 | G30: 58510 | I30: EPS (Diluted) | J30: 9.39 | K30: 8.04 | L30: 5.8 | M30: 4.56 | N30: 5.61 | O30: 2.93 | Q30: Net Cash Flow | R30: -6189 | S30: -582 | T30: 2169 | U30: 934 | V30: -5520 | W30: 7967 | Y30: Earnings Yield | Z30: 0.0389 | AA30: 0.0431 | AB30: 0.042 | AC30: 0.0524 | AD30: 0.0396 | AE30: 0.034
A31: Retained Earnings | B31: 275760 | C31: 245084 | D31: 211247 | E31: 195563 | F31: 191484 | G31: 163401 | I31: EPS Growth | J31: 0.347 | K31: 0.3867 | L31: 0.2728 | M31: -0.1876 | N31: 0.9143 | O31: 0.1922 | Q31: Free Cash Flow | R31: 66728 | S31: 72764 | T31: 69495 | U31: 60010 | V31: 67012 | W31: 42843 | Y31: FCF Yield | Z31: 0.0225 | AA31: 0.0313 | AB31: 0.0396 | AC31: 0.0524 | AD31: 0.0349 | AE31: 0.0362
A32: Comprehensive Income & Other | B32: -2127 | C32: -4800 | D32: -4402 | E32: -7603 | F32: -1623 | G32: 633 | I32: Free Cash Flow | J32: 66728 | K32: 72764 | L32: 69495 | M32: 60010 | N32: 67012 | O32: 42843 | Q32: Free Cash Flow Growth | R32: 0.0977 | S32: 0.047 | T32: 0.1581 | U32: -0.1045 | V32: 0.5641 | W32: 0.3833 | Y32: Dividend Yield | Z32: 0.0034 | AA32: 0.0042 | AB32: - | AC32: - | AD32: - | AE32: -
A33: Shareholders' Equity | B33: 362916 | C33: 325084 | D33: 283379 | E33: 256144 | F33: 251635 | G33: 222544 | I33: Free Cash Flow Per Share | J33: 5.42 | K33: 5.85 | L33: 5.46 | M33: 4.56 | N33: 4.94 | O33: 3.12 | Q33: Free Cash Flow Margin | R33: 0.1797 | S33: 0.2079 | T33: 0.2261 | U33: 0.2122 | V33: 0.2601 | W33: 0.2347 | Y33: Payout Ratio | Z33: 0.0895 | AA33: 0.0735 | AB33: - | AC33: - | AD33: - | AE33: -
A34: Total Liabilities & Equity | B34: 502053 | C34: 450256 | D34: 402392 | E34: 365264 | F34: 359268 | G34: 319616 | I34: Dividend Per Share | J34: 1.01 | K34: 0.8 | L34: - | M34: - | N34: - | O34: - | Q34: Free Cash Flow Per Share | R34: 5.42 | S34: 5.85 | T34: 5.46 | U34: 4.56 | V34: 4.94 | W34: 3.12 | Y34: Buyback Yield / Dilution | Z34: 0.0212 | AA34: 0.0216 | AB34: 0.0332 | AC34: 0.0291 | AD34: 0.0137 | AE34: 0.0165
A35: Total Debt | B35: 41668 | C35: 28137 | D35: 29787 | E35: 29977 | F35: 28508 | G35: 27872 | I35: Gross Margin | J35: 0.5894 | K35: 0.582 | L35: 0.5663 | M35: 0.5538 | N35: 0.5694 | O35: 0.5358 | Q35: Cash Income Tax Paid | R35: 27400 | S35: 27400 | T35: 19200 | U35: 18900 | V35: 13412 | W35: 4990 | Y35: Total Shareholder Return | Z35: 0.0246 | AA35: 0.0259 | AB35: 0.0332 | AC35: 0.0291 | AD35: 0.0137 | AE35: 0.0165
A36: Net Cash (Debt) | B36: 53480 | C36: 67520 | D36: 81129 | E36: 83785 | F36: 111141 | G36: 108822 | I36: Operating Margin | J36: 0.3316 | K36: 0.3262 | L36: 0.2742 | M36: 0.2646 | N36: 0.3055 | O36: 0.2259 | Q36: Levered Free Cash Flow | R36: 49787 | S36: 56581 | T36: 56280 | U36: 49939 | V36: 47009 | W36: 35504
A37: Net Cash Growth | B37: -0.2573 | C37: -0.1678 | D37: -0.0317 | E37: -0.2461 | F37: 0.0213 | G37: 0.0505 | I37: Profit Margin | J37: 0.3112 | K37: 0.286 | L37: 0.2401 | M37: 0.212 | N37: 0.2951 | O37: 0.2206 | Q37: Unlevered Free Cash Flow | R37: 50038 | S37: 56748 | T37: 56472 | U37: 50162 | V37: 47225 | W37: 35588
A38: Net Cash Per Share | B38: 4.34 | C38: 5.42 | D38: 6.38 | E38: 6.37 | F38: 8.2 | G38: 7.92 | I38: Free Cash Flow Margin | J38: 0.1797 | K38: 0.2079 | L38: 0.2261 | M38: 0.2122 | N38: 0.2601 | O38: 0.2347 | Q38: Change in Working Capital | R38: -8545 | S38: -8406 | T38: -3845 | U38: -2235 | V38: -1523 | W38: 1827
A39: Filing Date Shares Outstanding | B39: 12094 | C39: 12190 | D39: 12433 | E39: 12807 | F39: 13219 | G39: 13483 | I39: EBITDA | J39: 140841 | K39: 129497 | L39: 96239 | M39: 88317 | N39: 88987 | O39: 54903
A40: Total Common Shares Outstanding | B40: 12104 | C40: 12211 | D40: 12460 | E40: 12849 | F40: 13242 | G40: 13504 | I40: EBITDA Margin | J40: 0.3792 | K40: 0.37 | L40: 0.3131 | M40: 0.3123 | N40: 0.3454 | O40: 0.3008
...

Sheet DCF
A1: Alphabet Inc. (GOOGL) – 5-Year DCF Model
A2: Ticker: GOOGL | Valuation date: 10/14/2026 | $ in millions except per-share | Historicals from 'Annual Financial' (LTM = TTM ending 6/30/2025)
A4: Case selector (1 = Bear, 2 = Base, 3 = Bull) | B4: 2 | C4: =CHOOSE(B4,"Bear Case","Base Case","Bull Case") -> Base Case
A6: MARKET DATA & CAPITAL STRUCTURE
A7: Current share price ($) | B7: 353.78 | C7: Close 10/13/2026 – unofficial source (CNBC), see note
A8: Diluted shares outstanding (mm) | B8: ='Annual Financial'!J27 -> 12314 | C8: LTM diluted shares (6/30/2025)
A9: Market capitalization | B9: =B7*B8 -> 4356446.9
A10: Total debt | B10: ='Annual Financial'!B35 -> 41668
A11: Cash & short-term investments | B11: ='Annual Financial'!B6 -> 95148
A12: Net debt / (net cash) | B12: =B10-B11 -> -53480 | C12: Negative = net cash (added to equity value)
A13: Market enterprise value | B13: =B9+B12 -> 4302966.9
A15: BEAR CASE ASSUMPTIONS
A16: Assumption | H16: FY2026E | I16: FY2027E | J16: FY2028E | K16: FY2029E | L16: FY2030E
A17: Revenue growth (%) | H17: 0.1 | I17: 0.08 | J17: 0.07 | K17: 0.06 | L17: 0.05
A18: EBIT margin (%) | H18: 0.31 | I18: 0.305 | J18: 0.3 | K18: 0.3 | L18: 0.3
A19: Tax rate (%) | H19: 0.21 | I19: 0.21 | J19: 0.21 | K19: 0.21 | L19: 0.21
A20: D&A (% of revenue) | H20: 0.055 | I20: 0.065 | J20: 0.075 | K20: 0.08 | L20: 0.085
A21: CapEx (% of revenue) | H21: 0.21 | I21: 0.2 | J21: 0.18 | K21: 0.16 | L21: 0.14
A22: Δ NWC (% of Δ revenue) | H22: 0.15 | I22: 0.15 | J22: 0.15 | K22: 0.15 | L22: 0.15
A23: Terminal growth rate (%) | H23: 0.02
A24: WACC adjustment vs. base WACC (%) | H24: 0.01
A26: BASE CASE ASSUMPTIONS
A27: Assumption | H27: FY2026E | I27: FY2027E | J27: FY2028E | K27: FY2029E | L27: FY2030E
A28: Revenue growth (%) | B28: Starts from your draft (14/12/11/10/10%); LTM growth 13.1% | H28: 0.14 | I28: 0.12 | J28: 0.11 | K28: 0.1 | L28: 0.1
A29: EBIT margin (%) | B29: LTM EBIT margin 33.2%; FY24 32.6% | H29: 0.33 | I29: 0.34 | J29: 0.345 | K29: 0.35 | L29: 0.35
A30: Tax rate (%) | B30: LTM effective 17.3%; cash taxes ~20% of pretax | H30: 0.18 | I30: 0.18 | J30: 0.18 | K30: 0.18 | L30: 0.18
A31: D&A (% of revenue) | B31: LTM 4.8%; rises as AI capex depreciates | H31: 0.055 | I31: 0.065 | J31: 0.075 | K31: 0.08 | L31: 0.085
A32: CapEx (% of revenue) | B32: LTM 18.0% (FY24 15.0%); normalizes from AI build-out peak | H32: 0.2 | I32: 0.18 | J32: 0.16 | K32: 0.14 | L32: 0.12
A33: Δ NWC (% of Δ revenue) | B33: FY23-24 hist. ~16-20% of Δrev; assume 10% | H33: 0.1 | I33: 0.1 | J33: 0.1 | K33: 0.1 | L33: 0.1
A34: Terminal growth rate (%) | B34: Below LT nominal GDP and 10Y yield | H34: 0.025
A35: WACC adjustment vs. base WACC (%) | B35: Base = WACC sheet | H35: 0
A37: BULL CASE ASSUMPTIONS
A38: Assumption | H38: FY2026E | I38: FY2027E | J38: FY2028E | K38: FY2029E | L38: FY2030E
A39: Revenue growth (%) | H39: 0.17 | I39: 0.15 | J39: 0.13 | K39: 0.12 | L39: 0.11
A40: EBIT margin (%) | H40: 0.35 | I40: 0.36 | J40: 0.37 | K40: 0.375 | L40: 0.38
A41: Tax rate (%) | H41: 0.165 | I41: 0.165 | J41: 0.165 | K41: 0.165 | L41: 0.165
A42: D&A (% of revenue) | H42: 0.055 | I42: 0.065 | J42: 0.075 | K42: 0.08 | L42: 0.085
A43: CapEx (% of revenue) | H43: 0.19 | I43: 0.16 | J43: 0.14 | K43: 0.12 | L43: 0.1
A44: Δ NWC (% of Δ revenue) | H44: 0.05 | I44: 0.05 | J44: 0.05 | K44: 0.05 | L44: 0.05
A45: Terminal growth rate (%) | H45: 0.03
...

Sheet WACC
A1: Alphabet Inc. (GOOGL) – Weighted Average Cost of Capital
A2: $mm unless noted | Valuation date 10/14/2026
A4: COST OF EQUITY (CAPM)
A5: Risk-free rate (10Y UST) | B5: 0.0521 | C5: U.S. Treasury par yield, 10/13/2026
A6: Levered beta | B6: 1.2 | C6: CNBC (unofficial), see note
A7: Equity risk premium | B7: 0.055 | C7: Analyst assumption (mature-market ERP)
A8: Cost of equity | B8: =B5+B6*B7 -> 0.1181
A10: COST OF DEBT
A11: Credit spread over UST (AA+ rated) | B11: 0.006 | C11: Analyst assumption; Alphabet rated AA+ (S&P)
A12: Pre-tax cost of debt | B12: =B5+B11 -> 0.0581
A13: Tax rate | B13: =DCF!H52 -> 0.18
A14: After-tax cost of debt | B14: =B12*(1-B13) -> 0.047642
A16: CAPITAL STRUCTURE (MARKET VALUES)
A17: Market capitalization | B17: =DCF!B9 -> 4356446.9
A18: Total debt (incl. leases) | B18: =DCF!B10 -> 41668 | C18: Gross debt used for weights (Alphabet is net cash)
A19: Total capitalization | B19: =B17+B18 -> 4398114.9
A20: Equity weight | B20: =B17/B19 -> 0.99052594
A21: Debt weight | B21: =B18/B19 -> 0.0094740589
A23: WACC
A24: Base WACC | B24: =B20*B8+B21*B14 -> 0.11743248
A25: Scenario adjustment (selected case) | B25: =DCF!H57 -> 0 | C25: Bear +1.0% / Base 0% / Bull –1.0%
A26: WACC – selected case | B26: =B24+B25 -> 0.11743248
