Workbook
Name tgr: [1]DCF!$E$19
Name wacc: [1]DCF!$E$18

Sheet DCF
B2: DCF
B4: Ticker | C4: MU | E4: Implied Shere Price | G4: =C73 -> 378.69879
B5: Sheres Outstanding | C5: =WACC!F11 -> 1122.4666 | E5: Upside/Downside | G5: =(G4/C6)-1 -> -0.6274813
B6: Shere Price | C6: =WACC!F10 -> 1016.59
B7: Market Cap | C7: =C6*C5 -> 1141088.3 | E7: Enterprise Value | G7: =C71 -> 430121.74
B8: Date | C8: 46020 | E8: Equity Value | G8: =C72 -> 425076.74
B9: End Of Year | C9: 46022
B11: Asssumptions
B13: WACC | C13: =WACC!F27 -> 0.11752771
B14: TGR | C14: 0.025
B16: FY AUG | C16: 2022A | D16: 2023A | E16: 2024A | F16: 2025A | G16: 2026E | H16: 2027E | I16: 2028E | J16: 2029E | K16: 2030E | L16: 2031E | M16: 2032E
B18: Financials
B20: Revenue | C20: ='Income Statement'!F5 -> 30758 | D20: ='Income Statement'!G5 -> 15540 | E20: ='Income Statement'!H5 -> 25111 | F20: ='Income Statement'!I5 -> 37378 | G20: =F20*(1+G21) -> 73810.337 | H20: =G20*(1+H21) -> 90786.714 | I20: =H20*(1+I21) -> 106220.46 | J20: =I20*(1+J21) -> 118966.91 | K20: =J20*(1+K21) -> 128484.26 | L20: =K20*(1+L21) -> 135165.44 | M20: =L20*(1+M21) -> 142194.05
B21: % Growth | C21: =(C20-'Income Statement'!E5)/'Income Statement'!E5 -> 0.11019672 | D21: =(D20-C20)/C20 -> -0.49476559 | E21: =(E20-D20)/D20 -> 0.61589447 | F21: =(F20-E20)/E20 -> 0.48851101 | G21: 0.9747 | H21: 0.23 | I21: 0.17 | J21: 0.12 | K21: 0.08 | L21: 0.052 | M21: 0.052
B23: COGS Excluding D&A | C23: ='Income Statement'!F7 -> 9744 | D23: ='Income Statement'!G7 -> 9200 | E23: ='Income Statement'!H7 -> 11718 | F23: ='Income Statement'!I7 -> 14153 | G23: =G20*G25 -> 22143.101 | H23: =H20*H25 -> 29051.748 | I23: =I20*I25 -> 37177.159 | J23: =J20*J25 -> 38069.411 | K23: =K20*K25 -> 35975.594 | L23: =L20*L25 -> 37846.324 | M23: =M20*M25 -> 39814.333
B24: % Growth | C24: =(C23-'Income Statement'!E7)/'Income Statement'!E7 -> -0.11962414 | D24: =(D23-C23)/C23 -> -0.055829228 | E24: =(E23-D23)/D23 -> 0.27369565 | F24: =(F23-E23)/E23 -> 0.20779997 | G24: =(G23-F23)/F23 -> 0.56455175 | H24: =(H23-G23)/G23 -> 0.312 | I24: =(I23-H23)/H23 -> 0.2796875 | J24: =(J23-I23)/I23 -> 0.024 | K24: =(K23-J23)/J23 -> -0.055 | ... M24: =(M23-L23)/L23 -> 0.052
B25: % Of Revenue | C25: =C23/C20 -> 0.31679563 | D25: =D23/D20 -> 0.59202059 | E25: =E23/E20 -> 0.46664808 | F25: =F23/F20 -> 0.37864519 | G25: 0.3 | H25: 0.32 | I25: 0.35 | J25: 0.32 | K25: 0.28 | L25: 0.28 | M25: 0.28
B27: Gross Profit | C27: =C20-C23 -> 21014 | D27: =D20-D23 -> 6340 | E27: =E20-E23 -> 13393 | F27: =F20-F23 -> 23225 | G27: =G20-G23 -> 51667.236 | H27: =H20-H23 -> 61734.966 | I27: =I20-I23 -> 69043.296 | J27: =J20-J23 -> 80897.499 | ... M27: =M20-M23 -> 102379.71
B28: % Profit Margin | C28: =C27/C20 -> 0.68320437 | D28: =D27/D20 -> 0.40797941 | E28: =E27/E20 -> 0.53335192 | F28: =F27/F20 -> 0.62135481 | G28: =G27/G20 -> 0.7 | H28: =H27/H20 -> 0.68 | I28: =I27/I20 -> 0.65 | J28: =J27/J20 -> 0.68 | ... M28: =M27/M20 -> 0.72
B30: OpEx | C30: =SUM('Income Statement'!F10:F12) -> 4148 | D30: =SUM('Income Statement'!G10:G12) -> 4158 | E30: =SUM('Income Statement'!H10:H12) -> 4308 | F30: =SUM('Income Statement'!I10:I12) -> 5064 | G30: 5900 | H30: =H20*H31 -> 9078.6714 | I30: =I20*I31 -> 10622.046 | J30: =J20*J31 -> 11896.691 | K30: =K20*K31 -> 12848.426 | L30: =L20*L31 -> 13516.544 | M30: =M20*M31 -> 14219.405
B31: % Of Revenue | C31: =C30/C20 -> 0.13485922 | D31: =D30/D20 -> 0.26756757 | E31: =E30/E20 -> 0.17155828 | F31: =F30/F20 -> 0.13548076 | G31: =G30/G20 -> 0.079934604 | H31: 0.1 | I31: 0.1 | J31: 0.1 | K31: 0.1 | L31: 0.1 | M31: 0.1
B33: EBIT | C33: ='Income Statement'!F13 -> 9702 | D33: ='Income Statement'!G13 -> -5745 | E33: ='Income Statement'!H13 -> 1304 | F33: ='Income Statement'!I13 -> 9770 | G33: =G20-G23-G30 -> 45767.236 | H33: =H20-H23-H30 -> 52656.294 | I33: =I20-I23-I30 -> 58421.25 | J33: =J20-J23-J30 -> 69000.808 | K33: =K20-K23-K30 -> 79660.243 | L33: =L20-L23-L30 -> 83802.576 | M33: =M20-M23-M30 -> 88160.31
B34: % Growth | C34: =(C33-'Income Statement'!E13)/'Income Statement'!E13 -> 0.5441668 | D34: =(D33-C33)/C33 -> -1.5921459 | E34: =(E33-D33)/D33 -> -1.22698 | F34: =(F33-E33)/E33 -> 6.4923313 | G34: =(G33-F33)/F33 -> 3.6844663 | H34: =(H33-G33)/G33 -> 0.15052381 | I34: =(I33-H33)/H33 -> 0.10948276 | J34: =(J33-I33)/I33 -> 0.18109091 | K34: =(K33-J33)/J33 -> 0.15448276 | ... M34: =(M33-L33)/L33 -> 0.052
B35: % Of Revenue | C35: =C33/C20 -> 0.31543013 | D35: =D33/D20 -> -0.36969112 | E35: =E33/E20 -> 0.051929433 | F35: =F33/F20 -> 0.2613837 | G35: 0.42 | H35: 0.4 | I35: 0.35 | J35: 0.35 | K35: 0.35 | L35: 0.35 | M35: 0.35
B37: EBITDA | C37: ='Income Statement'!F34 -> 16818 | D37: ='Income Statement'!G34 -> 2011 | E37: ='Income Statement'!H34 -> 9084 | F37: ='Income Statement'!I34 -> 18122 | G37: =G33+G41 -> 56838.786 | H37: =H33+H41 -> 68997.903 | I37: =I33+I41 -> 79665.342 | J37: =J33+J41 -> 92794.19 | K37: =K33+K41 -> 105357.1 | L37: =L33+L41 -> 110835.66 | M37: =M33+M41 -> 116599.12
B38: % Growth | C38: =(C37-'Income Statement'!E34)/'Income Statement'!E34 -> 0.34576298 | D38: =(D37-C37)/C37 -> -0.88042573 | E38: =(E37-D37)/D37 -> 3.5171556 | F38: =(F37-E37)/E37 -> 0.99493615 | G38: =(G37-F37)/F37 -> 2.1364522 | H38: =(H37-G37)/G37 -> 0.21392288 | I38: =(I37-H37)/H37 -> 0.15460526 | J38: =(J37-I37)/I37 -> 0.1648 | K38: =(K37-J37)/J37 -> 0.13538462 | ... M38: =(M37-L37)/L37 -> 0.052
B39: % Of Revenue | C39: =C37/C20 -> 0.54678458 | D39: =D37/D20 -> 0.12940798 | E39: =E37/E20 -> 0.36175381 | F39: =F37/F20 -> 0.48483065 | G39: =G37/G20 -> 0.7700654 | H39: =H37/H20 -> 0.76 | I39: =I37/I20 -> 0.75 | J39: =J37/J20 -> 0.78 | ... M39: =M37/M20 -> 0.82
B41: D&A | C41: ='Cash Flow Statement'!F7 -> 7116 | D41: ='Cash Flow Statement'!G7 -> 7756 | E41: ='Cash Flow Statement'!H7 -> 7780 | F41: ='Cash Flow Statement'!I7 -> 8352 | G41: =G20*G43 -> 11071.55 | H41: =H20*H43 -> 16341.609 | I41: =I20*I43 -> 21244.091 | J41: =J20*J43 -> 23793.382 | K41: =K20*K43 -> 25696.853 | L41: =L20*L43 -> 27033.089 | M41: =M20*M43 -> 28438.81
B42: % Growth | C42: =(C41-'Income Statement'!E8)/'Income Statement'!E8 -> 0.1451561 | D42: =(D41-C41)/C41 -> 0.089938168 | E42: =(E41-D41)/D41 -> 0.0030943785 | F42: =(F41-E41)/E41 -> 0.073521851 | G42: =(G41-F41)/F41 -> 0.32561668 | H42: =(H41-G41)/G41 -> 0.476 | I42: =(I41-H41)/H41 -> 0.3 | J42: =(J41-I41)/I41 -> 0.12 | K42: =(K41-J41)/J41 -> 0.08 | ... M42: =(M41-L41)/L41 -> 0.052
B43: % Of Revenue | C43: =C41/C20 -> 0.23135444 | D43: =D41/D20 -> 0.4990991 | E43: =E41/E20 -> 0.30982438 | F43: =F41/F20 -> 0.22344695 | G43: 0.15 | H43: 0.18 | I43: 0.2 | J43: 0.2 | K43: 0.2 | L43: 0.2 | M43: 0.2
B45: Capex | C45: ='Cash Flow Statement'!F19 -> -12067 | D45: ='Cash Flow Statement'!G19 -> -7676 | E45: ='Cash Flow Statement'!H19 -> -8386 | F45: ='Cash Flow Statement'!I19 -> -15857 | G45: =G20*G47 -> 20666.894 | H45: =H20*H47 -> 27236.014 | I45: =I20*I47 -> 33990.546 | J45: =J20*J47 -> 38069.411 | K45: =K20*K47 -> 41114.964 | L45: =L20*L47 -> 43252.942 | M45: =M20*M47 -> 45502.095
B46: % Growth % Of Revenue | C46: =(C45-'Cash Flow Statement'!E19)/'Cash Flow Statement'!E19 -> 0.20309073 | D46: =(D45-C45)/C45 -> -0.36388498 | E46: =(E45-D45)/D45 -> 0.092496092 | F46: =(F45-E45)/E45 -> 0.89088958 | G46: =(G45-F45)/F45 -> -2.3033294 | H46: =(H45-G45)/G45 -> 0.31785714 | I46: =(I45-H45)/H45 -> 0.248 | J46: =(J45-I45)/I45 -> 0.12 | K46: =(K45-J45)/J45 -> 0.08 | ... M46: =(M45-L45)/L45 -> 0.052
B47: % Of Revenue | C47: =C45/-C20 -> 0.3923207 | D47: =D45/-D20 -> 0.49395109 | E47: =E45/-E20 -> 0.33395723 | F47: =F45/-F20 -> 0.42423351 | G47: 0.28 | H47: 0.3 | I47: 0.32 | J47: 0.32 | K47: 0.32 | L47: 0.32 | M47: 0.32
B49: Changes In Working capital | C49: ='Cash Flow Statement'!F11 -> -1263 | D49: ='Cash Flow Statement'!G11 -> -2892 | E49: ='Cash Flow Statement'!H11 -> -884 | F49: ='Cash Flow Statement'!I11 -> -338 | G49: =G20*G50 -> -1476.2067 | H49: =H20*H50 -> -1815.7343 | I49: =I20*I50 -> -2124.4091 | J49: =J20*J50 -> -2379.3382 | K49: =K20*K50 -> -2569.6853 | L49: =L20*L50 -> -2703.3089 | M49: =M20*M50 -> -2843.881
B50: % Of Revenue | C50: =C49/-C20 -> 0.041062488 | D50: =D49/-D20 -> 0.18610039 | E50: =E49/-E20 -> 0.035203696 | F50: =F49/-F20 -> 0.0090427524 | G50: -0.02 | H50: -0.02 | I50: -0.02 | J50: -0.02 | K50: -0.02 | L50: -0.02 | M50: -0.02
B52: Income tax (provision) benefit | C52: ='Income Statement'!F24 -> -888 | D52: ='Income Statement'!G24 -> -177 | E52: ='Income Statement'!H24 -> -451 | F52: ='Income Statement'!I24 -> -1124 | G52: =G20*G53 -> 11440.602 | H52: =H20*H53 -> 19065.21 | I52: =I20*I53 -> 22306.296 | J52: =J20*J53 -> 24983.051 | K52: =K20*K53 -> 26981.695 | L52: =L20*L53 -> 28384.743 | M52: =M20*M53 -> 29860.75
B53: % EffectiveTax Rate | G53: 0.155 | H53: 0.21 | I53: 0.21 | J53: 0.21 | K53: 0.21 | L53: 0.21 | M53: 0.21
B55: Net Income | C55: ='Income Statement'!F26 -> 8687 | D55: ='Income Statement'!G26 -> -5833 | E55: ='Income Statement'!H26 -> 778 | F55: ='Income Statement'!I26 -> 8539 | G55: =G33*(1-G53) -> 38673.314 | H55: =H33*(1-H53) -> 41598.472 | I55: =I33*(1-I53) -> 46152.788 | J55: =J33*(1-J53) -> 54510.638 | K55: =K33*(1-K53) -> 62931.592 | L55: =L33*(1-L53) -> 66204.035 | M55: =M33*(1-M53) -> 69646.645
B56: % Growth | C56: =(C55-'Income Statement'!E26)/'Income Statement'!E26 -> 0.48217028 | D56: =(D55-C55)/C55 -> -1.6714631 | E56: =(E55-D55)/D55 -> -1.1333791 | F56: =(F55-E55)/E55 -> 9.9755784 | G56: =(G55-F55)/F55 -> 3.5290214 | H56: =(H55-G55)/G55 -> 0.075637641 | I56: =(I55-H55)/H55 -> 0.10948276 | J56: =(J55-I55)/I55 -> 0.18109091 | K56: =(K55-J55)/J55 -> 0.15448276 | ... M56: =(M55-L55)/L55 -> 0.052
B57: % Of Revenue | C57: =C55/C20 -> 0.28243059 | D57: =D55/D20 -> -0.37535393 | E57: =E55/E20 -> 0.030982438 | F57: =F55/F20 -> 0.22844989 | G57: =G55/G20 -> 0.52395526 | H57: =H55/H20 -> 0.4582 | I57: =I55/I20 -> 0.4345 | J57: =J55/J20 -> 0.4582 | ... M57: =M55/M20 -> 0.4898
...

Sheet Executive Summary
A1: Defending the $390 Intrinsic Value of Micron Technology
A2: Executive Summary In the wake of the artificial intelligence infrastructure boom, the semiconductor memory sector has decoupled from its historical commodity cycles.
A3: A rigorous Discounted Cash Flow (DCF) analysis of Micron Technology (MU) reveals an intrinsic value of $390.14 per share, implying an upside of approximately 32% from current trading levels (~$294).
A4: This valuation, while aggressive relative to the consensus median, is firmly supported by the structural scarcity of High-Bandwidth Memory (HBM), the unprecedented operating leverage
A5: inherent in the current "Supercycle," and a convergence of bullish institutional research from firms such as Rosenblatt Securities and Morgan Stanley.
A7: The Revenue Imperative: Sold Out Through 2026 The cornerstone of this valuation is the projection of $73.8 billion in FY2026 revenue.
A8: Far from a "blue sky" estimate, this figure is grounded in the hard reality of the "Memory Wall."
A9: As noted by Bank of America analysts in their December 2025 notes, Micron’s entire HBM production capacity is officially sold out through the end of calendar year 2026.
A10: This transforms the company’s near-term revenue profile from a variable spot-market guess into a fixed annuity.
A11: The model’s revenue assumption perfectly aligns with management’s guidance and the consensus view that the displacement of commodity DDR5 capacity for HBM manufacturing will create
A12: a "double engine" of pricing power—lifting prices for both premium AI memory and standard server DRAM.
A14: The Profitability Engine: The "Rosenblatt" Scenario The most critical driver of the $390 valuation is the assumption of radical operating leverage—specifically, holding Operating Expenses (OpEx) near $6.0 billion while revenue doubles.
... A26: It is a conservative bull case that acknowledges the risks while refusing to ignore the mathematical reality of the AI Supercycle.

Sheet WACC
A1: WACC
B4: WACC = % of equity x cost of equity + % of debt x cost of debt x (1 - Tax Rate)
B5: Cost of equity = Risk free rate + Beta x Market Risk Premium
B8: WACC
B10: Shere Price | F10: {=_xlfn.TAKE(_xlfn.STOCKHISTORY("MU", TODAY()-7, TODAY()-1, 0, 0, 1), -1)} -> 1016.59
B11: Weighted Average Sheres Outstanding | F11: 1122.4666
B13: Market Cap | F13: =F11*F10 -> 1141088.3
B14: % of Equity | F14: =F13/$F$25 -> 0.98672478
B15: Cost of Equity | F15: =F16+(F17*F18) -> 0.11862
B16: Risk Free Rate | F16: 0.04112
B17: Beta | F17: 1.55
B18: Market Risk Premium | F18: 0.05
B20: Debt | F20: =15352 -> 15352
B21: % of Debt | F21: =F20/F25 -> 0.01327522
B22: Cost of Debt | F22: 0.046
B23: Tax Rate | F23: 0.21
B25: Total | F25: =F13+F20 -> 1156440.3
B27: WACC | F27: =F14*F15+(F21*F22*(1-F23)) -> 0.11752771

Sheet Cash Flow Statement
A1: Micron Technology, Inc. Ticker Mu
A2: {=_xlfn.TAKE(_xlfn.STOCKHISTORY("MU", TODAY()-7, TODAY()-1, 0, 0, 1), -1)} -> 1016.59
B4: AUG '18 | C4: AUG '19 | D4: AUG '20 | E4: AUG '21 | F4: AUG '22 | G4: AUG '23 | H4: AUG '24 | I4: AUG '25
A5: Operating Activities
A6: Net Income / Starting Line | B6: ='Income Statement'!B26 -> 14138 | C6: ='Income Statement'!C26 -> 6358 | D6: ='Income Statement'!D26 -> 2710 | E6: ='Income Statement'!E26 -> 5861 | F6: ='Income Statement'!F26 -> 8687 | G6: ='Income Statement'!G26 -> -5833 | H6: ='Income Statement'!H26 -> 778 | I6: ='Income Statement'!I26 -> 8539
A7: Depreciation, Depletion & Amortization | B7: ='Income Statement'!B8 -> 4759 | C7: ='Income Statement'!C8 -> 5424 | D7: ='Income Statement'!D8 -> 5650 | E7: ='Income Statement'!E8 -> 6214 | F7: ='Income Statement'!F8 -> 7116 | G7: ='Income Statement'!G8 -> 7756 | H7: ='Income Statement'!H8 -> 7780 | I7: ='Income Statement'!I8 -> 8352
A8: Other Funds | B8: 101 | C8: 49 | D8: 26 | E8: 454 | F8: 44 | G8: =1831+101 -> 1932 | H8: 0 | I8: 0
A9: Stock Based Comp | B9: 198 | C9: 243 | D9: 328 | E9: 378 | F9: 514 | G9: 596 | H9: 833 | I9: 972
A10: (Gains) losses on debt prepayments, repurchases, and conversions | B10: 385 | C10: 396 | D10: -40 | E10: 1 | F10: 83 | G10: 0 | H10: 0 | I10: 0
A11: Changes in Working Capital | B11: =SUM(B12:B16) -> -2181 | C11: =SUM(C12:C16) -> 719 | D11: =SUM(D12:D16) -> -368 | E11: =SUM(E12:E16) -> -440 | F11: =SUM(F12:F16) -> -1263 | G11: =SUM(G12:G16) -> -2892 | H11: =SUM(H12:H16) -> -884 | I11: =SUM(I12:I16) -> -338
A12: Receivables | B12: -1734 | C12: 2431 | D12: -723 | E12: -1446 | F12: 190 | G12: 2763 | H12: -3581 | I12: -1776
A13: Inventories | B13: -472 | C13: -1528 | D13: -489 | E13: 866 | F13: -2179 | G13: -3555 | H13: -488 | I13: 520
A14: Accounts Payable | B14: 668 | C14: -174 | D14: 725 | E14: 210 | F14: 744 | G14: -1302 | H14: 1915 | I14: 862
A15: Other | B15: -378 | C15: -160 | D15: 40 | E15: -70 | F15: -18 | G15: =-817+19 -> -798 | H15: =989+281 -> 1270 | I15: =-272+328 -> 56
A16: Defferred income Taxes net | B16: -265 | C16: 150 | D16: 79 | E16: 0 | F16: 0 | G16: 0 | H16: 0 | I16: 0
A17: Net Operating Cash Flow | B17: =B6+SUM(B7:B16) -> 15219 | C17: =C6+SUM(C7:C16) -> 13908 | D17: =D6+SUM(D7:D16) -> 7938 | E17: =E6+SUM(E7:E16) -> 12028 | F17: =F6+SUM(F7:F16) -> 13918 | G17: =G6+SUM(G7:G16) -> -1333 | H17: =H6+SUM(H7:H16) -> 7623 | I17: =I6+SUM(I7:I16) -> 17187
A18: Investing Activities
A19: Capital Expenditures | B19: -8879 | C19: -9780 | D19: -8223 | E19: -10030 | F19: -12067 | G19: -7676 | H19: -8386 | I19: -15857
A20: Purchase/Sale of Investments | B20: -760 | C20: -4218 | D20: -1857 | E20: -3163 | F20: -1770 | G20: -723 | H20: -1999 | I20: -1890
A21: Proceeds from sales of available-for-sale securities | B21: 604 | C21: 1504 | D21: 1458 | E21: 856 | F21: 294 | G21: 1591 | H21: 1794 | I21: 1698
A22: Proceeds from maturities of available-for-sale securities | B22: 320 | C22: 1541 | D22: 814 | E22: 1250 | F22: 1321 | G22: 0 | H22: 0 | I22: 0
A23: Proceeds from government incentives | B23: 355 | C23: 748 | D23: 262 | E23: 495 | F23: 115 | G23: 710 | H23: 315 | I23: 2005
A24: Other | B24: 144 | C24: 120 | D24: -43 | E24: 3 | F24: =888-366 -> 522 | G24: -93 | H24: -33 | I24: -43
A25: Sale/Maturity of Investments | B25: =B22+B21 -> 924 | C25: =C22+C21 -> 3045 | D25: =D22+D21 -> 2272 | E25: =E22+E21 -> 2106 | F25: =F22+F21 -> 1615 | G25: =G22+G21 -> 1591 | H25: =H22+H21 -> 1794 | I25: =I22+I21 -> 1698
A26: Net Investing Cash Flow | B26: =SUM(B19:B24) -> -8216 | C26: =SUM(C19:C24) -> -10085 | D26: =SUM(D19:D24) -> -7589 | E26: =SUM(E19:E24) -> -10589 | F26: =SUM(F19:F24) -> -11585 | G26: =SUM(G19:G24) -> -6191 | H26: =SUM(H19:H24) -> -8309 | I26: =SUM(I19:I24) -> -14087
A27: Financing Activities
A28: Repayments Of Debt | B28: -10194 | C28: -3340 | D28: -4366 | E28: -1520 | F28: -2032 | G28: -761 | H28: -1897 | I28: -4619
A29: Acquisition of noncontrolling intrest in IMFT | B29: 0 | C29: 0 | D29: -744 | E29: 0 | F29: 0 | G29: 0 | H29: 0 | I29: 0
A30: Payments to acquire treasury stock | B30: -71 | C30: -2729 | D30: -251 | E30: -1200 | F30: -2432 | G30: -425 | H30: -300 | I30: 0
A31: Payments Of Dividends to Shareholders | B31: 0 | C31: 0 | D31: 0 | E31: 0 | F31: -461 | G31: -504 | H31: -513 | I31: -522
A32: Payment on equipment purchase contracts | B32: -206 | C32: -75 | D32: -63 | E32: -295 | F32: -141 | G32: -138 | H32: -149 | I32: 0
A33: Proceads From Issuance of Debt | B33: 1009 | C33: 3550 | D33: 5000 | E33: 1188 | F33: 2000 | G33: 6716 | H33: 999 | I33: 4430
A34: Proceads From Issuance of Stock | B34: 1655 | C34: 179 | D34: 225 | E34: 140 | F34: 211 | G34: 0 | H34: 0 | I34: 0
A35: Other | B35: 31 | C35: -23 | D35: -118 | E35: =140-94 -> 46 | F35: =211-125 -> 86 | G35: 95 | H35: 18 | I35: -139
A36: Net Financing Cash Flow | B36: =SUM(B28:B35) -> -7776 | C36: =SUM(C28:C35) -> -2438 | D36: =SUM(D28:D35) -> -317 | E36: =SUM(E28:E35)-E34 -> -1781 | F36: =SUM(F28:F35)-F34 -> -2980 | G36: =SUM(G28:G35) -> 4983 | H36: =SUM(H28:H35) -> -1842 | I36: =SUM(I28:I35) -> -850
A37: All Activities
A38: Exchange Rate Effect | B38: -37 | C38: 26 | D38: 11 | E38: 41 | F38: -106 | G38: -34 | H38: 40 | I38: 6
A39: Net Change in Cash | B39: =B17+B26+B36+B38 -> -810 | C39: =C17+C26+C36+C38 -> 1411 | D39: =D17+D26+D36+D38 -> 43 | E39: =E17+E26+E36+E38 -> -301 | F39: =F17+F26+F36+F38 -> -753 | G39: =G17+G26+G36+G38 -> -2575 | H39: =H17+H26+H36+H38 -> -2488 | I39: =I17+I26+I36+I38 -> 2256
A40: Free Cash Flow | B40: =B17+B19 -> 6340 | C40: =C17+C19 -> 4128 | D40: =D17+D19 -> -285 | E40: =E17+E19 -> 1998 | F40: =F17+F19 -> 1851 | G40: =G17+G19 -> -9009 | H40: =H17+H19 -> -763 | I40: =I17+I19 -> 1330
A41: Free Cash Flow per Share | B41: =B40/'Income Statement'!B30 -> 5.5034722 | C41: =C40/'Income Statement'!C30 -> 3.7055655 | D41: =D40/'Income Statement'!D30 -> -0.25675676 | E41: =E40/'Income Statement'!E30 -> 1.7839286 | F41: =F40/'Income Statement'!F30 -> 1.6645683 | G41: =G40/'Income Statement'!G30 -> -8.242452 | H41: =H40/'Income Statement'!H30 -> -0.69049774 | I41: =I40/'Income Statement'!I30 -> 1.1917563
...

Sheet Income Statement
A1: Micron Technology, Inc. Ticker MU
A2: {=_xlfn.TAKE(_xlfn.STOCKHISTORY("MU", TODAY()-7, TODAY()-1, 0, 0, 1), -1)} -> 1016.59
B4: AUG '18 | C4: AUG '19 | D4: AUG '20 | E4: AUG '21 | F4: AUG '22 | G4: AUG '23 | H4: AUG '24 | I4: AUG '25
A5: Revenue | B5: 30391 | C5: 23406 | D5: 21435 | E5: 27705 | F5: 30758 | G5: 15540 | H5: 25111 | I5: 37378
A6: Cost of Goods Sold (COGS) incl. D&A | B6: 12500 | C6: 12704 | D6: 14883 | E6: 17282 | F6: 16860 | G6: 16956 | H6: 19498 | I6: 22505
A7: COGS excluding D&A | B7: =B6-B8 -> 7741 | C7: =C6-C8 -> 7280 | D7: =D6-D8 -> 9233 | E7: =E6-E8 -> 11068 | F7: =F6-F8 -> 9744 | G7: =G6-G8 -> 9200 | H7: =H6-H8 -> 11718 | I7: =I6-I8 -> 14153
A8: Depreciation & Amortization Expense | B8: 4759 | C8: 5424 | D8: 5650 | E8: 6214 | F8: 7116 | G8: 7756 | H8: 7780 | I8: 8352
A9: Gross Income | B9: =B5-B6 -> 17891 | C9: =C5-C6 -> 10702 | D9: =D5-D6 -> 6552 | E9: =E5-E6 -> 10423 | F9: =F5-F6 -> 13898 | G9: =G5-G6 -> -1416 | H9: =H5-H6 -> 5613 | I9: =I5-I6 -> 14873
A10: SG&A Expense | B10: 813 | C10: 836 | D10: 881 | E10: 894 | F10: 1066 | G10: 920 | H10: 1129 | I10: 1205
A11: Research & Development | B11: 2141 | C11: 2441 | D11: 2600 | E11: 2663 | F11: 3116 | G11: 3114 | H11: 3430 | I11: 3798
A12: Other Operating Expense | B12: -57 | C12: 49 | D12: 68 | E12: 95 | F12: -34 | G12: 124 | H12: -251 | I12: 61
A13: EBIT (Operating Income) | B13: =B5-B6-SUM(B10:B12)-B19 -> 14994 | C13: =C5-C6-SUM(C10:C12)-C19 -> 7376 | D13: =D5-D6-SUM(D10:D12)-D19 -> 3003 | E13: =E5-E6-SUM(E10:E12)-E19 -> 6283 | F13: =F5-F6-SUM(F10:F12)-F19 -> 9702 | G13: =G5-G6-SUM(G10:G12)-G19 -> -5745 | H13: =H5-H6-SUM(H10:H12)-H19 -> 1304 | I13: =I5-I6-SUM(I10:I12)-I19 -> 9770
A14: Nonoperating Income - Net | B14: =B15-B17+B16 -> -687 | C14: =C15-C17+C16 -> -328 | D14: =D15-D17+D16 -> -20 | E14: =E15-E17+E16 -> -65 | F14: =F15-F17+F16 -> -131 | G14: =G15-G17+G16 -> 87 | H14: =H15-H17+H16 -> -64 | I14: =I15-I17+I16 -> -116
A15: Nonoperating Interest Income | B15: 120 | C15: 205 | D15: 114 | E15: 37 | F15: 96 | G15: 468 | H15: 529 | I15: 496
A16: Other Income (Expense) | B16: -465 | C16: -405 | D16: 60 | E16: 81 | F16: -38 | G16: 7 | H16: -31 | I16: -135
A17: Interest Expense | B17: 342 | C17: 128 | D17: 194 | E17: 183 | F17: 189 | G17: 388 | H17: 562 | I17: 477
A18: Gross Interest Expense | B18: =B17-B15 -> 222 | C18: =C17-C15 -> -77 | D18: =D17-D15 -> 80 | E18: =E17-E15 -> 146 | F18: =F17-F15 -> 93 | G18: =G17-G15 -> -80 | H18: =H17-H15 -> 33 | I18: =I17-I15 -> -19
A19: Unusual Expense - Net | B19: 0 | C19: 0 | D19: 0 | E19: 488 | F19: 48 | G19: 171 | H19: 1 | I19: 39
A20: Unrealized Valuation Gain/Loss | B20: =B21+B22 -> -17 | C20: =C21+C22 -> 6 | D20: =D21+D22 -> 47 | E20: =E21+E22 -> -74 | F20: =F21+F22 -> -564 | G20: 6 | H20: 33 | I20: 4
A21: Investments | B21: -2 | C21: 9 | D21: 1 | E21: -7 | F21: -48 | G21: 234 | H21: 142 | I21: 92
A22: Hedges/Derivatives | B22: -15 | C22: -3 | D22: 46 | E22: -67 | F22: -516 | G22: 234 | H22: 142 | I22: 92
A23: Pretax Income | B23: =B13+B14 -> 14307 | C23: =C13+C14 -> 7048 | D23: =D13+D14 -> 2983 | E23: =E13+E14 -> 6218 | F23: =F13+F14 -> 9571 | G23: =G13+G14 -> -5658 | H23: =H13+H14 -> 1240 | I23: =I13+I14 -> 9654
A24: Income tax (provision) benefit | B24: -168 | C24: -693 | D24: -280 | E24: -394 | F24: -888 | G24: -177 | H24: -451 | I24: -1124
A25: Equity in net income (loss) of equity method investees | B25: -1 | C25: 3 | D25: 7 | E25: 37 | F25: 4 | G25: 2 | H25: -11 | I25: 9
A26: Net Income | B26: =B25+B23+B24 -> 14138 | C26: =C25+C23+C24 -> 6358 | D26: =D25+D23+D24 -> 2710 | E26: =E25+E23+E24 -> 5861 | F26: =F25+F23+F24 -> 8687 | G26: =G25+G23+G24 -> -5833 | H26: =H25+H23+H24 -> 778 | I26: =I25+I23+I24 -> 8539
A27: Net Income available to Common | B27: 14135 | C27: 6313 | D27: 2687 | E27: 5861 | F27: 8687 | G27: =G26 -> -5833 | H27: =H26 -> 778 | I27: =I26 -> 8539
A28: Per Share
A29: EPS (basic) | B29: =B27/B30 -> 12.269965 | C29: =C27/C30 -> 5.6669659 | D29: =D27/D30 -> 2.4207207 | E29: =E27/E30 -> 5.2330357 | F29: =F27/F30 -> 7.8120504 | G29: =G27/G30 -> -5.336688 | H29: =H27/H30 -> 0.7040724 | I29: =I27/I30 -> 7.6514337
A30: Basic Shares Outstanding | B30: 1152 | C30: 1114 | D30: 1110 | E30: 1120 | F30: 1112 | G30: 1093 | H30: 1105 | I30: 1116
A31: EPS (diluted) | B31: =B27/B32 -> 11.501221 | C31: =C27/C32 -> 5.5231846 | D31: =D27/D32 -> 2.3757737 | E31: =E27/E32 -> 5.1367222 | F31: =F27/F32 -> 7.7424242 | G31: =G27/G32 -> -5.336688 | H31: =H27/H32 -> 0.69588551 | I31: =I27/I32 -> 7.5902222
A32: Diluted Shares Outstanding | B32: 1229 | C32: 1143 | D32: 1131 | E32: 1141 | F32: 1122 | G32: 1093 | H32: 1118 | I32: 1125
A33: EBITDA
A34: EBITDA | B34: =B35+B36 -> 19753 | C34: =C35+C36 -> 12800 | D34: =D35+D36 -> 8653 | E34: =E35+E36 -> 12497 | F34: =F35+F36 -> 16818 | G34: =G35+G36 -> 2011 | H34: =H35+H36 -> 9084 | I34: =I35+I36 -> 18122
A35: EBIT | B35: =B13 -> 14994 | C35: =C13 -> 7376 | D35: =D13 -> 3003 | E35: =E13 -> 6283 | F35: =F13 -> 9702 | G35: =G13 -> -5745 | H35: =H13 -> 1304 | I35: =I13 -> 9770
A36: Depreciation & Amortization Expense | B36: =B8 -> 4759 | C36: =C8 -> 5424 | D36: =D8 -> 5650 | E36: =E8 -> 6214 | F36: =F8 -> 7116 | G36: =G8 -> 7756 | H36: =H8 -> 7780 | I36: =I8 -> 8352
A37: All figures in millions of U.S. Dollar except per share items.
